Traceback (most recent call last):
  File "/usr/lib/python3/dist-packages/serial/serialposix.py", line 322, in open
    self.fd = os.open(self.portstr, os.O_RDWR | os.O_NOCTTY | os.O_NONBLOCK)
FileNotFoundError: [Errno 2] No such file or directory: '/dev/ttyACM1'

During handling of the above exception, another exception occurred:

Traceback (most recent call last):
  File "/home/pi/Desktop/git/Design-IV/main.py", line 96, in <module>
    main()
  File "/home/pi/Desktop/git/Design-IV/main.py", line 24, in main
    config_file = setup()
  File "/home/pi/Desktop/git/Design-IV/main.py", line 78, in setup
    hardware.setup_hardware_access()
  File "/home/pi/Desktop/git/Design-IV/Control/hardwareAccess.py", line 75, in setup_hardware_access
    self.setup_serials()
  File "/home/pi/Desktop/git/Design-IV/Control/hardwareAccess.py", line 103, in setup_serials
    ser = serial.Serial(
  File "/usr/lib/python3/dist-packages/serial/serialutil.py", line 244, in __init__
    self.open()
  File "/usr/lib/python3/dist-packages/serial/serialposix.py", line 325, in open
    raise SerialException(msg.errno, "could not open port {}: {}".format(self._port, msg))
serial.serialutil.SerialException: [Errno 2] could not open port /dev/ttyACM1: [Errno 2] No such file or directory: '/dev/ttyACM1'
